Workbook
Name Slicer_DIA__STATUS: #N/A
Name Slicer_WE__STATUS: #N/A

Sheet Customer Names
A1: Customer ID | B1: TITLE | C1: FIRST NAME | D1: LAST NAME
A2: Id1 | B2: Ms | C2: Hawks | D2: Kelly
A3: Id2 | B3: Mr | C3: Lehner | D3: Matthew D
A4: Id3 | B4: Mr | C4: Lu | D4: Phil
A5: Id4 | B5: Ms | C5: Osborne | D5: Kelsey
A6: Id5 | B6: Ms | C6: Kadala | D6: Kristyn
A7: Id6 | B7: Mr | C7: Baker | D7: Russell B
A8: Id7 | B8: Mr | C8: Macpherson | D8: Scott
A9: Id8 | B9: Mr | C9: Hallman | D9: Stephen
A10: Id9 | B10: Mr | C10: Moran | D10: Patrick R
A11: Id10 | B11: Ms | C11: Benner | D11: Brooke N
A12: Id11 | B12: Ms | C12: Fierro Vargas | D12: Paola Andrea
... A72: Id71 | B72: Mr | C72: Turner | D72: Jeff
A73: Id72 | B73: Mr | C73: Rangel | D73: Elenilton V | E73: Sr
A74: Id73 | B74: Ms | C74: Lacey | D74: Maurya
A75: Id74 | B75: Ms | C75: Stiger | D75: Samantha C
A76: Id75 | B76: Ms | C76: Caldwell | D76: Bethany A
A77: Id76 | B77: Mr | C77: Marmillod | D77: Yves
A78: Id77 | B78: Ms | C78: Cloutier-Simons | D78: Danielle
A79: Id78 | B79: Ms | C79: Vegas | D79: Julia
A80: Id79 | B80: Mr | C80: Cochran | D80: Joshua
A81: Id80 | B81: Ms | C81: Holtzapple | D81: Jennifer
A82: Id81 | B82: Ms | C82: Meyer | D82: Gwen M
A83: Id82 | B83: Mr | C83: Brickley | D83: Patrick
A84: Id83 | B84: Ms | C84: Magee | D84: Kate
A85: Id84 | B85: Mr | C85: Thoma | D85: Kevin
... A188: Id187 | B188: Mr | C188: Dublin | D188: Andrew P
A189: Id188 | B189: Mr | C189: Cleland | D189: George M | E189: V
A190: Id189 | B190: Ms | C190: Evans | D190: Sarah
A191: Id190 | B191: Ms | C191: Boyd | D191: Lara
A192: Id191 | B192: Mr | C192: Roulier | D192: Sebastien
A193: Id192 | B193: Mr | C193: Mullins | D193: Padraig
A194: Id193 | B194: Ms | C194: Hofmann | D194: Heather
A195: Id194 | B195: Mr | C195: Garcia Garcia | D195: Jorge
A196: Id195 | B196: Mr | C196: Klecker | D196: Jack R
A197: Id196 | B197: Mr | C197: Cancre | D197: Felix
A198: Id197 | B198: Mr | C198: Denucci | D198: Christopher C
A199: Id198 | B199: Mr | C199: Saldana | D199: Jesse
A200: Id199 | B200: Ms | C200: Weinberg | D200: Jill
A201: Id200 | B201: Mr | C201: Walsh | D201: William
...

Sheet Sheet3
A3: Row Labels | B3: Count of yes
A4: ? | B4: 2
A5: No | B5: 1845
A6: yes | B6: 487
A7: Grand Total | B7: 2334

Sheet Medical Examinations
A1: Customer ID | B1: BMI | C1: HBA1C | D1: Heart Issues | E1: Any Transplants | F1: Cancer history | G1: NumberOfMajorSurgeries | H1: smoker | I1: Weight Status | J1: Diabetes Status
A2: Id1 | B2: 47.41 | C2: 7.47 | D2: No | E2: No | F2: No | G2: 0 | H2: Yes | I2: =IF(B2<18.5,"underweight",IF(B2<=24.9,"normal weight",IF(B2<=29.9,"overweight",IF(B2>30,"obesity")))) -> obesity | J2: =IF(C2<5.7,"normal",IF(C2<=6.4, "prediabetes",IF(C2>6.5,"diabetes"))) -> diabetes
A3: Id2 | B3: 30.36 | C3: 5.77 | D3: No | E3: No | F3: No | G3: 0 | H3: Yes | I3: =IF(B3<18.5,"underweight",IF(B3<=24.9,"normal weight",IF(B3<=29.9,"overweight",IF(B3>30,"obesity")))) -> obesity | J3: =IF(C3<5.7,"normal",IF(C3<=6.4, "prediabetes",IF(C3>6.5,"diabetes"))) -> prediabetes
A4: Id3 | B4: 34.485 | C4: 11.87 | D4: Yes | E4: No | F4: No | G4: 2 | H4: Yes | I4: =IF(B4<18.5,"underweight",IF(B4<=24.9,"normal weight",IF(B4<=29.9,"overweight",IF(B4>30,"obesity")))) -> obesity | J4: =IF(C4<5.7,"normal",IF(C4<=6.4, "prediabetes",IF(C4>6.5,"diabetes"))) -> diabetes
A5: Id4 | B5: 38.095 | C5: 6.05 | D5: No | E5: No | F5: No | G5: 0 | H5: Yes | I5: =IF(B5<18.5,"underweight",IF(B5<=24.9,"normal weight",IF(B5<=29.9,"overweight",IF(B5>30,"obesity")))) -> obesity | J5: =IF(C5<5.7,"normal",IF(C5<=6.4, "prediabetes",IF(C5>6.5,"diabetes"))) -> prediabetes
A6: Id5 | B6: 35.53 | C6: 5.45 | D6: No | E6: No | F6: No | G6: 0 | H6: Yes | I6: =IF(B6<18.5,"underweight",IF(B6<=24.9,"normal weight",IF(B6<=29.9,"overweight",IF(B6>30,"obesity")))) -> obesity | J6: =IF(C6<5.7,"normal",IF(C6<=6.4, "prediabetes",IF(C6>6.5,"diabetes"))) -> normal
A7: Id6 | B7: 32.8 | C7: 6.59 | D7: No | E7: No | F7: No | G7: 0 | H7: Yes | I7: =IF(B7<18.5,"underweight",IF(B7<=24.9,"normal weight",IF(B7<=29.9,"overweight",IF(B7>30,"obesity")))) -> obesity | J7: =IF(C7<5.7,"normal",IF(C7<=6.4, "prediabetes",IF(C7>6.5,"diabetes"))) -> diabetes
A8: Id7 | B8: 36.4 | C8: 6.07 | D8: No | E8: No | F8: No | G8: 0 | H8: Yes | I8: =IF(B8<18.5,"underweight",IF(B8<=24.9,"normal weight",IF(B8<=29.9,"overweight",IF(B8>30,"obesity")))) -> obesity | J8: =IF(C8<5.7,"normal",IF(C8<=6.4, "prediabetes",IF(C8>6.5,"diabetes"))) -> prediabetes
A9: Id8 | B9: 36.96 | C9: 7.93 | D9: No | E9: No | F9: No | G9: 3 | H9: Yes | I9: =IF(B9<18.5,"underweight",IF(B9<=24.9,"normal weight",IF(B9<=29.9,"overweight",IF(B9>30,"obesity")))) -> obesity | J9: =IF(C9<5.7,"normal",IF(C9<=6.4, "prediabetes",IF(C9>6.5,"diabetes"))) -> diabetes
A10: Id9 | B10: 41.14 | C10: 9.58 | D10: Yes | E10: No | F10: Yes | G10: 1 | H10: Yes | I10: =IF(B10<18.5,"underweight",IF(B10<=24.9,"normal weight",IF(B10<=29.9,"overweight",IF(B10>30,"obesity")))) -> obesity | J10: =IF(C10<5.7,"normal",IF(C10<=6.4, "prediabetes",IF(C10>6.5,"diabetes"))) -> diabetes
A11: Id10 | B11: 38.06 | C11: 10.79 | D11: No | E11: No | F11: No | G11: 0 | H11: Yes | I11: =IF(B11<18.5,"underweight",IF(B11<=24.9,"normal weight",IF(B11<=29.9,"overweight",IF(B11>30,"obesity")))) -> obesity | J11: =IF(C11<5.7,"normal",IF(C11<=6.4, "prediabetes",IF(C11>6.5,"diabetes"))) -> diabetes
A12: Id11 | B12: 37.7 | C12: 5.96 | D12: Yes | E12: No | F12: No | G12: 2 | H12: Yes | I12: =IF(B12<18.5,"underweight",IF(B12<=24.9,"normal weight",IF(B12<=29.9,"overweight",IF(B12>30,"obesity")))) -> obesity | J12: =IF(C12<5.7,"normal",IF(C12<=6.4, "prediabetes",IF(C12>6.5,"diabetes"))) -> prediabetes
A13: Id12 | B13: 42.13 | C13: 11.9 | D13: No | E13: No | F13: No | G13: 0 | H13: Yes | I13: =IF(B13<18.5,"underweight",IF(B13<=24.9,"normal weight",IF(B13<=29.9,"overweight",IF(B13>30,"obesity")))) -> obesity | J13: =IF(C13<5.7,"normal",IF(C13<=6.4, "prediabetes",IF(C13>6.5,"diabetes"))) -> diabetes
... A2336: Id2335 | B2336: 17.58 | C2336: 4.51 | D2336: No | E2336: No | F2336: No | G2336: 1 | H2336: No | I2336: =IF(B2336<18.5,"underweight",IF(B2336<=24.9,"normal weight",IF(B2336<=29.9,"overweight",IF(B2336>30,"obesity")))) -> underweight | J2336: =IF(C2336<5.7,"normal",IF(C2336<=6.4, "prediabetes",IF(C2336>6.5,"diabetes"))) -> normal

Sheet Hospitalisation Details
A1: Customer ID | B1: customer id | C1: year | D1: month | E1: date | F1: DOB | G1: children | H1: charges | I1: Hospital tier | J1: City tier | K1: State ID | L1: Age
A2: Id1 | B2: =VALUE(MID(A2,3,LEN(A2)-2)) -> 1 | C2: 1968 | D2: Oct | E2: 12 | F2: =DATE(C2, MONTH(1&D2), E2) -> 25123 | G2: 0 | H2: 63770.43 | I2: tier - 1 | J2: tier - 3 | K2: R1013 | L2: =DATEDIF(F2, DATE(2023,6,8), "Y") -> 54
A3: Id2 | B3: =VALUE(MID(A3,3,LEN(A3)-2)) -> 2 | C3: 1977 | D3: Jun | E3: 8 | F3: =DATE(C3, MONTH(1&D3), E3) -> 28284 | G3: 0 | H3: 62592.87 | I3: tier - 2 | J3: tier - 3 | K3: R1013 | L3: =DATEDIF(F3, DATE(2023,6,8), "Y") -> 46
A4: Id3 | B4: =VALUE(MID(A4,3,LEN(A4)-2)) -> 3 | C4: 1970 | D4: september | E4: 11 | F4: =DATE(C4, MONTH(1&D4), E4) -> 25822 | G4: 3 | H4: 60021.4 | I4: tier - 1 | J4: tier - 1 | K4: R1012 | L4: =DATEDIF(F4, DATE(2023,6,8), "Y") -> 52
A5: Id4 | B5: =VALUE(MID(A5,3,LEN(A5)-2)) -> 4 | C5: 1991 | D5: Jun | E5: 6 | F5: =DATE(C5, MONTH(1&D5), E5) -> 33395 | G5: 1 | H5: 58571.07 | I5: tier - 1 | J5: tier - 3 | K5: R1024 | L5: =DATEDIF(F5, DATE(2023,6,8), "Y") -> 32
A6: Id5 | B6: =VALUE(MID(A6,3,LEN(A6)-2)) -> 5 | C6: 1989 | D6: Jun | E6: 19 | F6: =DATE(C6, MONTH(1&D6), E6) -> 32678 | G6: 0 | H6: 55135.4 | I6: tier - 1 | J6: tier - 2 | K6: R1012 | L6: =DATEDIF(F6, DATE(2023,6,8), "Y") -> 33
A7: Id6 | B7: =VALUE(MID(A7,3,LEN(A7)-2)) -> 6 | C7: 1962 | D7: Aug | E7: 4 | F7: =DATE(C7, MONTH(1&D7), E7) -> 22862 | G7: 0 | H7: 52590.83 | I7: tier - 1 | J7: tier - 3 | K7: R1011 | L7: =DATEDIF(F7, DATE(2023,6,8), "Y") -> 60
A8: Id7 | B8: =VALUE(MID(A8,3,LEN(A8)-2)) -> 7 | C8: 1994 | D8: Oct | E8: 27 | F8: =DATE(C8, MONTH(1&D8), E8) -> 34634 | G8: 1 | H8: 51194.56 | I8: tier - 1 | J8: tier - 3 | K8: R1011 | L8: =DATEDIF(F8, DATE(2023,6,8), "Y") -> 28
A9: Id8 | B9: =VALUE(MID(A9,3,LEN(A9)-2)) -> 8 | C9: 1958 | D9: Jun | E9: 27 | F9: =DATE(C9, MONTH(1&D9), E9) -> 21363 | G9: 2 | H9: 49577.66 | I9: tier - 2 | J9: tier - 2 | K9: R1013 | L9: =DATEDIF(F9, DATE(2023,6,8), "Y") -> 64
A10: Id9 | B10: =VALUE(MID(A10,3,LEN(A10)-2)) -> 9 | C10: 1963 | D10: Sep | E10: 4 | F10: =DATE(C10, MONTH(1&D10), E10) -> 23258 | G10: 1 | H10: 48970.25 | I10: tier - 1 | J10: tier - 2 | K10: R1013 | L10: =DATEDIF(F10, DATE(2023,6,8), "Y") -> 59
A11: Id10 | B11: =VALUE(MID(A11,3,LEN(A11)-2)) -> 10 | C11: 1978 | D11: Dec | E11: 29 | F11: =DATE(C11, MONTH(1&D11), E11) -> 28853 | G11: 0 | H11: 48885.14 | I11: tier - 1 | J11: tier - 2 | K11: R1013 | L11: =DATEDIF(F11, DATE(2023,6,8), "Y") -> 44
A12: Id11 | B12: =VALUE(MID(A12,3,LEN(A12)-2)) -> 11 | C12: 1959 | D12: Jul | E12: 22 | F12: =DATE(C12, MONTH(1&D12), E12) -> 21753 | G12: 0 | H12: 48824.45 | I12: tier - 2 | J12: tier - 1 | K12: R1011 | L12: =DATEDIF(F12, DATE(2023,6,8), "Y") -> 63
A13: Id12 | B13: =VALUE(MID(A13,3,LEN(A13)-2)) -> 12 | C13: 1965 | D13: Oct | E13: 27 | F13: =DATE(C13, MONTH(1&D13), E13) -> 24042 | G13: 1 | H13: 48675.52 | I13: tier - 1 | J13: tier - 2 | K13: R1013 | L13: =DATEDIF(F13, DATE(2023,6,8), "Y") -> 57
... A2338: id3444 | B2338: =VALUE(MID(A2338,3,LEN(A2338)-2)) -> 3444 | C2338: 2004 | D2338: Nov | E2338: 1 | F2338: =DATE(C2338, MONTH(1&D2338), E2338) -> 38292 | G2338: 2 | H2338: 34303.17 | I2338: tier - 1 | J2338: tier - 3 | K2338: R1013 | L2338: =DATEDIF(F2338, DATE(2023,6,8), "Y") -> 18
A2339: ="id"&ROW()-1 -> id2338 | B2339: =VALUE(MID(A2339,3,LEN(A2339)-2)) -> 2338 | C2339: 2004 | D2339: Nov | E2339: 6 | F2339: =DATE(C2339, MONTH(1&D2339), E2339) -> 38297 | G2339: 0 | H2339: 1137.01 | I2339: tier - 3 | J2339: tier - 1 | K2339: R1013 | L2339: =DATEDIF(F2339, DATE(2023,6,8), "Y") -> 18
A2340: ="id"&ROW()-1 -> id2339 | B2340: =VALUE(MID(A2340,3,LEN(A2340)-2)) -> 2339 | C2340: 1999 | D2340: Jun | E2340: 9 | F2340: =DATE(C2340, MONTH(1&D2340), E2340) -> 36320 | G2340: 1 | H2340: 2775.19 | I2340: tier - 2 | J2340: tier - 1 | K2340: R1012 | L2340: =DATEDIF(F2340, DATE(2023,6,8), "Y") -> 23
A2341: ="id"&ROW()-1 -> id2340 | B2341: =VALUE(MID(A2341,3,LEN(A2341)-2)) -> 2340 | C2341: 1985 | D2341: Dec | E2341: 20 | F2341: =DATE(C2341, MONTH(1&D2341), E2341) -> 31401 | G2341: 2 | H2341: 6203.9 | I2341: tier - 1 | J2341: tier - 2 | K2341: R1012 | L2341: =DATEDIF(F2341, DATE(2023,6,8), "Y") -> 37
A2342: ="id"&ROW()-1 -> id2341 | B2342: =VALUE(MID(A2342,3,LEN(A2342)-2)) -> 2341 | C2342: 2000 | D2342: Oct | E2342: 13 | F2342: =DATE(C2342, MONTH(1&D2342), E2342) -> 36812 | G2342: 0 | H2342: 35585.58 | I2342: tier - 1 | J2342: tier - 2 | K2342: R1011 | L2342: =DATEDIF(F2342, DATE(2023,6,8), "Y") -> 22
A2343: ="id"&ROW()-1 -> id2342 | B2343: =VALUE(MID(A2343,3,LEN(A2343)-2)) -> 2342 | C2343: 1992 | D2343: Oct | E2343: 6 | F2343: =DATE(C2343, MONTH(1&D2343), E2343) -> 33883 | G2343: 0 | H2343: 36837.47 | I2343: tier - 1 | J2343: tier - 2 | K2343: R1011 | L2343: =DATEDIF(F2343, DATE(2023,6,8), "Y") -> 30
A2344: ="id"&ROW()-1 -> id2343 | B2344: =VALUE(MID(A2344,3,LEN(A2344)-2)) -> 2343 | C2344: 1991 | D2344: Nov | E2344: 22 | F2344: =DATE(C2344, MONTH(1&D2344), E2344) -> 33564 | G2344: 2 | H2344: 38711 | I2344: tier - 1 | J2344: tier - 3 | K2344: R1011 | L2344: =DATEDIF(F2344, DATE(2023,6,8), "Y") -> 31
D2346: missing values | E2346: =COUNTIF(A2:K2344,"?") -> 0
D2348: average year | E2348: =ROUND(AVERAGEIF(C2:C2344,"<>?",C2:C2344),0) -> 1983

Sheet Sheet1
A3: Count of Customer ID | B3: Column Labels
A4: Row Labels | B4: No | C4: Yes | D4: Grand Total
A5: No | B5: 1540 | C5: 307 | D5: 1847
A6: Yes | B6: 404 | C6: 84 | D6: 488
A7: Grand Total | B7: 1944 | C7: 391 | D7: 2335

Sheet Sheet5
A3: Row Labels | B3: Sum of NO OF MAJOR SUR | C3: Average of HBA1C
A4: No | B4: 1417 | C4: 6.6704427
A5: yes | B5: 162 | C5: 5.1876389
A6: Grand Total | B6: 1579 | C6: 6.5789979

Sheet Sheet8
A3: Average of CHARGES | B3: Column Labels
A4: Row Labels | B4: diabetes | C4: normal | D4: prediabetes | E4: Grand Total
A5: normal weight | B5: 12491.075 | C5: 7897.0779 | D5: 10389.963 | E5: 9824.1346
A6: obesity | B6: 19375.184 | C6: 15217.015 | D6: 15550.437 | E6: 16730.321
A7: overweight | B7: 14154.532 | C7: 10376.643 | D7: 10008.416 | E7: 11467.175
A8: underweight | B8: 7442.9649 | C8: 6911.0056 | D8: 5626.0918 | E8: 6903.0043
A9: Grand Total | B9: 16145.014 | C9: 12116.017 | D9: 12690.245 | E9: 13579.556

Sheet Sheet9
A3: Average of CHARGES | B3: Column Labels
A4: Row Labels | B4: tier - 1 | C4: tier - 2 | D4: tier - 3 | E4: Grand Total
A5: R1011 | B5: 33081.374 | C5: 18997.281 | D5: 9250.3618 | E5: 19466.246
A6: R1012 | B6: 26111.458 | C6: 10334.279 | D6: 10179.942 | E6: 12016.474
A7: R1013 | B7: 31328.102 | C7: 8459.9777 | D7: 6854.5536 | E7: 10514.94
A8: R1014 | B8: 13891.86 | C8: 2395.17 | D8: 16950.485 | E8: 13478.057
A9: R1015 | B9: 21523.52 | C9: 15675.543 | D9: 7570.755 | E9: 13948.61
A10: R1016 | B10: 39868.616 | C10: 16075.963 | D10: 8133.0084 | E10: 13589.263
A11: R1017 | B11: 34070.596 | C11: 11365.622 | D11: 8667.3662 | E11: 14806.108
A12: R1018 | B12: 33475.82 | C12: 10139.553 | D12: 12570.97 | E12: 13272.787
A13: R1019 | B13: 27621.61 | C13: 8116.72 | D13: 12706.976 | E13: 13633.143
A14: R1020 | C14: 6760.5433 | D14: 11716.453 | E14: 9238.4983
A15: R1021 | C15: 7668.1787 | D15: 11518.786 | E15: 8933.3781
A16: R1022 | C16: 10102.027 | D16: 11637.812 | E16: 10650.521
A17: R1023 | B17: 18261.757 | C17: 13457.095 | D17: 12785.637 | E17: 13786.149
A18: R1024 | B18: 32732.187 | C18: 10174.346 | D18: 13360.979 | E18: 12865.149
A19: R1025 | C19: 6886.0368 | D19: 10510.314 | E19: 8788.7823
A20: R1026 | B20: 18709.798 | C20: 11919.608 | D20: 12296.78 | E20: 12489.921
A21: Grand Total | B21: 30189.68 | C21: 11873.62 | D21: 9449.6436 | E21: 13523.517

Sheet HEALTH CARE
A1: Customer ID | B1: NAME | C1: BMI | D1: HBA1C | E1: HERAT ISSUES | F1: ANY TRANSPLANTS | G1: CANCER HISTORY | H1: NO OF MAJOR SUR | I1: SMOKER | J1: WE STATUS | K1: DIA STATUS | L1: DOB | M1: CHARGES | N1: HOSPITAL TIRES | O1: CITY TIER | P1: STATE ID | Q1: AGE
A2: Id1 | B2: =VLOOKUP('HEALTH CARE'!A2,'Customer Names'!A2:D2,3,FALSE) -> Hawks | C2: =VLOOKUP(A2,'Medical Examinations'!A2:B2,2,FALSE) -> 47.41 | D2: =VLOOKUP(A2,'Medical Examinations'!A2:C2,3,FALSE) -> 7.47 | E2: =VLOOKUP(A2,'Medical Examinations'!A2:D2,4,FALSE) -> No | F2: =VLOOKUP(A2,'Medical Examinations'!A2:E2,5,FALSE) -> No | G2: =VLOOKUP(A2,'Medical Examinations'!A2:F2,6,FALSE) -> No | H2: =VLOOKUP('HEALTH CARE'!A2,'Medical Examinations'!A2:G2,7,FALSE) -> 0 | I2: =VLOOKUP(A2,'Medical Examinations'!A2:H2,8,FALSE) -> Yes | J2: =VLOOKUP(A2,'Medical Examinations'!A2:I2,9,FALSE) -> obesity | K2: =VLOOKUP(A2,'Medical Examinations'!A2:J2,10,FALSE) -> diabetes | L2: =VLOOKUP(A2,'Hospitalisation Details'!A:F, 5, FALSE) -> 12 | M2: =VLOOKUP(A2,'Hospitalisation Details'!A2:H2,8,FALSE) -> 63770.43 | N2: =VLOOKUP(A2,'Hospitalisation Details'!A2:I2,9,FALSE) -> tier - 1 | O2: =VLOOKUP(A2,'Hospitalisation Details'!A2:J2,10,FALSE) -> tier - 3 | P2: =VLOOKUP(A2,'Hospitalisation Details'!A2:K2,11,FALSE) -> R1013 | Q2: =VLOOKUP(A2,'Hospitalisation Details'!A2:L2,12,FALSE) -> 54
A3: Id2 | B3: =VLOOKUP('HEALTH CARE'!A3,'Customer Names'!A3:D3,3,FALSE) -> Lehner | C3: =VLOOKUP(A3,'Medical Examinations'!A3:B3,2,FALSE) -> 30.36 | D3: =VLOOKUP(A3,'Medical Examinations'!A3:C3,3,FALSE) -> 5.77 | E3: =VLOOKUP(A3,'Medical Examinations'!A3:D3,4,FALSE) -> No | F3: =VLOOKUP(A3,'Medical Examinations'!A3:E3,5,FALSE) -> No | G3: =VLOOKUP(A3,'Medical Examinations'!A3:F3,6,FALSE) -> No | H3: =VLOOKUP('HEALTH CARE'!A3,'Medical Examinations'!A3:G3,7,FALSE) -> 0 | I3: =VLOOKUP(A3,'Medical Examinations'!A3:H3,8,FALSE) -> Yes | J3: =VLOOKUP(A3,'Medical Examinations'!A3:I3,9,FALSE) -> obesity | K3: =VLOOKUP(A3,'Medical Examinations'!A3:J3,10,FALSE) -> prediabetes | L3: =VLOOKUP(A3,'Hospitalisation Details'!A:F, 5, FALSE) -> 8 | M3: =VLOOKUP(A3,'Hospitalisation Details'!A3:H3,8,FALSE) -> 62592.87 | N3: =VLOOKUP(A3,'Hospitalisation Details'!A3:I3,9,FALSE) -> tier - 2 | O3: =VLOOKUP(A3,'Hospitalisation Details'!A3:J3,10,FALSE) -> tier - 3 | P3: =VLOOKUP(A3,'Hospitalisation Details'!A3:K3,11,FALSE) -> R1013 | Q3: =VLOOKUP(A3,'Hospitalisation Details'!A3:L3,12,FALSE) -> 46
A4: Id3 | B4: =VLOOKUP('HEALTH CARE'!A4,'Customer Names'!A4:D4,3,FALSE) -> Lu | C4: =VLOOKUP(A4,'Medical Examinations'!A4:B4,2,FALSE) -> 34.485 | D4: =VLOOKUP(A4,'Medical Examinations'!A4:C4,3,FALSE) -> 11.87 | E4: =VLOOKUP(A4,'Medical Examinations'!A4:D4,4,FALSE) -> Yes | F4: =VLOOKUP(A4,'Medical Examinations'!A4:E4,5,FALSE) -> No | G4: =VLOOKUP(A4,'Medical Examinations'!A4:F4,6,FALSE) -> No | H4: =VLOOKUP('HEALTH CARE'!A4,'Medical Examinations'!A4:G4,7,FALSE) -> 2 | I4: =VLOOKUP(A4,'Medical Examinations'!A4:H4,8,FALSE) -> Yes | J4: =VLOOKUP(A4,'Medical Examinations'!A4:I4,9,FALSE) -> obesity | K4: =VLOOKUP(A4,'Medical Examinations'!A4:J4,10,FALSE) -> diabetes | L4: =VLOOKUP(A4,'Hospitalisation Details'!A:F, 5, FALSE) -> 11 | M4: =VLOOKUP(A4,'Hospitalisation Details'!A4:H4,8,FALSE) -> 60021.4 | N4: =VLOOKUP(A4,'Hospitalisation Details'!A4:I4,9,FALSE) -> tier - 1 | O4: =VLOOKUP(A4,'Hospitalisation Details'!A4:J4,10,FALSE) -> tier - 1 | P4: =VLOOKUP(A4,'Hospitalisation Details'!A4:K4,11,FALSE) -> R1012 | Q4: =VLOOKUP(A4,'Hospitalisation Details'!A4:L4,12,FALSE) -> 52
A5: Id4 | B5: =VLOOKUP('HEALTH CARE'!A5,'Customer Names'!A5:D5,3,FALSE) -> Osborne | C5: =VLOOKUP(A5,'Medical Examinations'!A5:B5,2,FALSE) -> 38.095 | D5: =VLOOKUP(A5,'Medical Examinations'!A5:C5,3,FALSE) -> 6.05 | E5: =VLOOKUP(A5,'Medical Examinations'!A5:D5,4,FALSE) -> No | F5: =VLOOKUP(A5,'Medical Examinations'!A5:E5,5,FALSE) -> No | G5: =VLOOKUP(A5,'Medical Examinations'!A5:F5,6,FALSE) -> No | H5: =VLOOKUP('HEALTH CARE'!A5,'Medical Examinations'!A5:G5,7,FALSE) -> 0 | I5: =VLOOKUP(A5,'Medical Examinations'!A5:H5,8,FALSE) -> Yes | J5: =VLOOKUP(A5,'Medical Examinations'!A5:I5,9,FALSE) -> obesity | K5: =VLOOKUP(A5,'Medical Examinations'!A5:J5,10,FALSE) -> prediabetes | L5: =VLOOKUP(A5,'Hospitalisation Details'!A:F, 5, FALSE) -> 6 | M5: =VLOOKUP(A5,'Hospitalisation Details'!A5:H5,8,FALSE) -> 58571.07 | N5: =VLOOKUP(A5,'Hospitalisation Details'!A5:I5,9,FALSE) -> tier - 1 | O5: =VLOOKUP(A5,'Hospitalisation Details'!A5:J5,10,FALSE) -> tier - 3 | P5: =VLOOKUP(A5,'Hospitalisation Details'!A5:K5,11,FALSE) -> R1024 | Q5: =VLOOKUP(A5,'Hospitalisation Details'!A5:L5,12,FALSE) -> 32
A6: Id5 | B6: =VLOOKUP('HEALTH CARE'!A6,'Customer Names'!A6:D6,3,FALSE) -> Kadala | C6: =VLOOKUP(A6,'Medical Examinations'!A6:B6,2,FALSE) -> 35.53 | D6: =VLOOKUP(A6,'Medical Examinations'!A6:C6,3,FALSE) -> 5.45 | E6: =VLOOKUP(A6,'Medical Examinations'!A6:D6,4,FALSE) -> No | F6: =VLOOKUP(A6,'Medical Examinations'!A6:E6,5,FALSE) -> No | G6: =VLOOKUP(A6,'Medical Examinations'!A6:F6,6,FALSE) -> No | H6: =VLOOKUP('HEALTH CARE'!A6,'Medical Examinations'!A6:G6,7,FALSE) -> 0 | I6: =VLOOKUP(A6,'Medical Examinations'!A6:H6,8,FALSE) -> Yes | J6: =VLOOKUP(A6,'Medical Examinations'!A6:I6,9,FALSE) -> obesity | K6: =VLOOKUP(A6,'Medical Examinations'!A6:J6,10,FALSE) -> normal | L6: =VLOOKUP(A6,'Hospitalisation Details'!A:F, 5, FALSE) -> 19 | M6: =VLOOKUP(A6,'Hospitalisation Details'!A6:H6,8,FALSE) -> 55135.4 | N6: =VLOOKUP(A6,'Hospitalisation Details'!A6:I6,9,FALSE) -> tier - 1 | O6: =VLOOKUP(A6,'Hospitalisation Details'!A6:J6,10,FALSE) -> tier - 2 | P6: =VLOOKUP(A6,'Hospitalisation Details'!A6:K6,11,FALSE) -> R1012 | Q6: =VLOOKUP(A6,'Hospitalisation Details'!A6:L6,12,FALSE) -> 33
A7: Id6 | B7: =VLOOKUP('HEALTH CARE'!A7,'Customer Names'!A7:D7,3,FALSE) -> Baker | C7: =VLOOKUP(A7,'Medical Examinations'!A7:B7,2,FALSE) -> 32.8 | D7: =VLOOKUP(A7,'Medical Examinations'!A7:C7,3,FALSE) -> 6.59 | E7: =VLOOKUP(A7,'Medical Examinations'!A7:D7,4,FALSE) -> No | F7: =VLOOKUP(A7,'Medical Examinations'!A7:E7,5,FALSE) -> No | G7: =VLOOKUP(A7,'Medical Examinations'!A7:F7,6,FALSE) -> No | H7: =VLOOKUP('HEALTH CARE'!A7,'Medical Examinations'!A7:G7,7,FALSE) -> 0 | I7: =VLOOKUP(A7,'Medical Examinations'!A7:H7,8,FALSE) -> Yes | J7: =VLOOKUP(A7,'Medical Examinations'!A7:I7,9,FALSE) -> obesity | K7: =VLOOKUP(A7,'Medical Examinations'!A7:J7,10,FALSE) -> diabetes | L7: =VLOOKUP(A7,'Hospitalisation Details'!A:F, 5, FALSE) -> 4 | M7: =VLOOKUP(A7,'Hospitalisation Details'!A7:H7,8,FALSE) -> 52590.83 | N7: =VLOOKUP(A7,'Hospitalisation Details'!A7:I7,9,FALSE) -> tier - 1 | O7: =VLOOKUP(A7,'Hospitalisation Details'!A7:J7,10,FALSE) -> tier - 3 | P7: =VLOOKUP(A7,'Hospitalisation Details'!A7:K7,11,FALSE) -> R1011 | Q7: =VLOOKUP(A7,'Hospitalisation Details'!A7:L7,12,FALSE) -> 60
A8: Id7 | B8: =VLOOKUP('HEALTH CARE'!A8,'Customer Names'!A8:D8,3,FALSE) -> Macpherson | C8: =VLOOKUP(A8,'Medical Examinations'!A8:B8,2,FALSE) -> 36.4 | D8: =VLOOKUP(A8,'Medical Examinations'!A8:C8,3,FALSE) -> 6.07 | E8: =VLOOKUP(A8,'Medical Examinations'!A8:D8,4,FALSE) -> No | F8: =VLOOKUP(A8,'Medical Examinations'!A8:E8,5,FALSE) -> No | G8: =VLOOKUP(A8,'Medical Examinations'!A8:F8,6,FALSE) -> No | H8: =VLOOKUP('HEALTH CARE'!A8,'Medical Examinations'!A8:G8,7,FALSE) -> 0 | I8: =VLOOKUP(A8,'Medical Examinations'!A8:H8,8,FALSE) -> Yes | J8: =VLOOKUP(A8,'Medical Examinations'!A8:I8,9,FALSE) -> obesity | K8: =VLOOKUP(A8,'Medical Examinations'!A8:J8,10,FALSE) -> prediabetes | L8: =VLOOKUP(A8,'Hospitalisation Details'!A:F, 5, FALSE) -> 27 | M8: =VLOOKUP(A8,'Hospitalisation Details'!A8:H8,8,FALSE) -> 51194.56 | N8: =VLOOKUP(A8,'Hospitalisation Details'!A8:I8,9,FALSE) -> tier - 1 | O8: =VLOOKUP(A8,'Hospitalisation Details'!A8:J8,10,FALSE) -> tier - 3 | P8: =VLOOKUP(A8,'Hospitalisation Details'!A8:K8,11,FALSE) -> R1011 | Q8: =VLOOKUP(A8,'Hospitalisation Details'!A8:L8,12,FALSE) -> 28
A9: Id8 | B9: =VLOOKUP('HEALTH CARE'!A9,'Customer Names'!A9:D9,3,FALSE) -> Hallman | C9: =VLOOKUP(A9,'Medical Examinations'!A9:B9,2,FALSE) -> 36.96 | D9: =VLOOKUP(A9,'Medical Examinations'!A9:C9,3,FALSE) -> 7.93 | E9: =VLOOKUP(A9,'Medical Examinations'!A9:D9,4,FALSE) -> No | F9: =VLOOKUP(A9,'Medical Examinations'!A9:E9,5,FALSE) -> No | G9: =VLOOKUP(A9,'Medical Examinations'!A9:F9,6,FALSE) -> No | H9: =VLOOKUP('HEALTH CARE'!A9,'Medical Examinations'!A9:G9,7,FALSE) -> 3 | I9: =VLOOKUP(A9,'Medical Examinations'!A9:H9,8,FALSE) -> Yes | J9: =VLOOKUP(A9,'Medical Examinations'!A9:I9,9,FALSE) -> obesity | K9: =VLOOKUP(A9,'Medical Examinations'!A9:J9,10,FALSE) -> diabetes | L9: =VLOOKUP(A9,'Hospitalisation Details'!A:F, 5, FALSE) -> 27 | M9: =VLOOKUP(A9,'Hospitalisation Details'!A9:H9,8,FALSE) -> 49577.66 | N9: =VLOOKUP(A9,'Hospitalisation Details'!A9:I9,9,FALSE) -> tier - 2 | O9: =VLOOKUP(A9,'Hospitalisation Details'!A9:J9,10,FALSE) -> tier - 2 | P9: =VLOOKUP(A9,'Hospitalisation Details'!A9:K9,11,FALSE) -> R1013 | Q9: =VLOOKUP(A9,'Hospitalisation Details'!A9:L9,12,FALSE) -> 64
A10: Id9 | B10: =VLOOKUP('HEALTH CARE'!A10,'Customer Names'!A10:D10,3,FALSE) -> Moran | C10: =VLOOKUP(A10,'Medical Examinations'!A10:B10,2,FALSE) -> 41.14 | D10: =VLOOKUP(A10,'Medical Examinations'!A10:C10,3,FALSE) -> 9.58 | E10: =VLOOKUP(A10,'Medical Examinations'!A10:D10,4,FALSE) -> Yes | F10: =VLOOKUP(A10,'Medical Examinations'!A10:E10,5,FALSE) -> No | G10: =VLOOKUP(A10,'Medical Examinations'!A10:F10,6,FALSE) -> Yes | H10: =VLOOKUP('HEALTH CARE'!A10,'Medical Examinations'!A10:G10,7,FALSE) -> 1 | I10: =VLOOKUP(A10,'Medical Examinations'!A10:H10,8,FALSE) -> Yes | J10: =VLOOKUP(A10,'Medical Examinations'!A10:I10,9,FALSE) -> obesity | K10: =VLOOKUP(A10,'Medical Examinations'!A10:J10,10,FALSE) -> diabetes | L10: =VLOOKUP(A10,'Hospitalisation Details'!A:F, 5, FALSE) -> 4 | M10: =VLOOKUP(A10,'Hospitalisation Details'!A10:H10,8,FALSE) -> 48970.25 | N10: =VLOOKUP(A10,'Hospitalisation Details'!A10:I10,9,FALSE) -> tier - 1 | O10: =VLOOKUP(A10,'Hospitalisation Details'!A10:J10,10,FALSE) -> tier - 2 | P10: =VLOOKUP(A10,'Hospitalisation Details'!A10:K10,11,FALSE) -> R1013 | Q10: =VLOOKUP(A10,'Hospitalisation Details'!A10:L10,12,FALSE) -> 59
A11: Id10 | B11: =VLOOKUP('HEALTH CARE'!A11,'Customer Names'!A11:D11,3,FALSE) -> Benner | C11: =VLOOKUP(A11,'Medical Examinations'!A11:B11,2,FALSE) -> 38.06 | D11: =VLOOKUP(A11,'Medical Examinations'!A11:C11,3,FALSE) -> 10.79 | E11: =VLOOKUP(A11,'Medical Examinations'!A11:D11,4,FALSE) -> No | F11: =VLOOKUP(A11,'Medical Examinations'!A11:E11,5,FALSE) -> No | G11: =VLOOKUP(A11,'Medical Examinations'!A11:F11,6,FALSE) -> No | H11: =VLOOKUP('HEALTH CARE'!A11,'Medical Examinations'!A11:G11,7,FALSE) -> 0 | I11: =VLOOKUP(A11,'Medical Examinations'!A11:H11,8,FALSE) -> Yes | J11: =VLOOKUP(A11,'Medical Examinations'!A11:I11,9,FALSE) -> obesity | K11: =VLOOKUP(A11,'Medical Examinations'!A11:J11,10,FALSE) -> diabetes | L11: =VLOOKUP(A11,'Hospitalisation Details'!A:F, 5, FALSE) -> 29 | M11: =VLOOKUP(A11,'Hospitalisation Details'!A11:H11,8,FALSE) -> 48885.14 | N11: =VLOOKUP(A11,'Hospitalisation Details'!A11:I11,9,FALSE) -> tier - 1 | O11: =VLOOKUP(A11,'Hospitalisation Details'!A11:J11,10,FALSE) -> tier - 2 | P11: =VLOOKUP(A11,'Hospitalisation Details'!A11:K11,11,FALSE) -> R1013 | Q11: =VLOOKUP(A11,'Hospitalisation Details'!A11:L11,12,FALSE) -> 44
A12: Id11 | B12: =VLOOKUP('HEALTH CARE'!A12,'Customer Names'!A12:D12,3,FALSE) -> Fierro Vargas | C12: =VLOOKUP(A12,'Medical Examinations'!A12:B12,2,FALSE) -> 37.7 | D12: =VLOOKUP(A12,'Medical Examinations'!A12:C12,3,FALSE) -> 5.96 | E12: =VLOOKUP(A12,'Medical Examinations'!A12:D12,4,FALSE) -> Yes | F12: =VLOOKUP(A12,'Medical Examinations'!A12:E12,5,FALSE) -> No | G12: =VLOOKUP(A12,'Medical Examinations'!A12:F12,6,FALSE) -> No | H12: =VLOOKUP('HEALTH CARE'!A12,'Medical Examinations'!A12:G12,7,FALSE) -> 2 | I12: =VLOOKUP(A12,'Medical Examinations'!A12:H12,8,FALSE) -> Yes | J12: =VLOOKUP(A12,'Medical Examinations'!A12:I12,9,FALSE) -> obesity | K12: =VLOOKUP(A12,'Medical Examinations'!A12:J12,10,FALSE) -> prediabetes | L12: =VLOOKUP(A12,'Hospitalisation Details'!A:F, 5, FALSE) -> 22 | M12: =VLOOKUP(A12,'Hospitalisation Details'!A12:H12,8,FALSE) -> 48824.45 | N12: =VLOOKUP(A12,'Hospitalisation Details'!A12:I12,9,FALSE) -> tier - 2 | O12: =VLOOKUP(A12,'Hospitalisation Details'!A12:J12,10,FALSE) -> tier - 1 | P12: =VLOOKUP(A12,'Hospitalisation Details'!A12:K12,11,FALSE) -> R1011 | Q12: =VLOOKUP(A12,'Hospitalisation Details'!A12:L12,12,FALSE) -> 63
A13: Id12 | B13: =VLOOKUP('HEALTH CARE'!A13,'Customer Names'!A13:D13,3,FALSE) -> Franz | C13: =VLOOKUP(A13,'Medical Examinations'!A13:B13,2,FALSE) -> 42.13 | D13: =VLOOKUP(A13,'Medical Examinations'!A13:C13,3,FALSE) -> 11.9 | E13: =VLOOKUP(A13,'Medical Examinations'!A13:D13,4,FALSE) -> No | F13: =VLOOKUP(A13,'Medical Examinations'!A13:E13,5,FALSE) -> No | G13: =VLOOKUP(A13,'Medical Examinations'!A13:F13,6,FALSE) -> No | H13: =VLOOKUP('HEALTH CARE'!A13,'Medical Examinations'!A13:G13,7,FALSE) -> 0 | I13: =VLOOKUP(A13,'Medical Examinations'!A13:H13,8,FALSE) -> Yes | J13: =VLOOKUP(A13,'Medical Examinations'!A13:I13,9,FALSE) -> obesity | K13: =VLOOKUP(A13,'Medical Examinations'!A13:J13,10,FALSE) -> diabetes | L13: =VLOOKUP(A13,'Hospitalisation Details'!A:F, 5, FALSE) -> 27 | M13: =VLOOKUP(A13,'Hospitalisation Details'!A13:H13,8,FALSE) -> 48675.52 | N13: =VLOOKUP(A13,'Hospitalisation Details'!A13:I13,9,FALSE) -> tier - 1 | O13: =VLOOKUP(A13,'Hospitalisation Details'!A13:J13,10,FALSE) -> tier - 2 | P13: =VLOOKUP(A13,'Hospitalisation Details'!A13:K13,11,FALSE) -> R1013 | Q13: =VLOOKUP(A13,'Hospitalisation Details'!A13:L13,12,FALSE) -> 57
... A2336: Id2335 | B2336: =VLOOKUP('HEALTH CARE'!A2336,'Customer Names'!A2336:D2336,3,FALSE) -> German | C2336: =VLOOKUP(A2336,'Medical Examinations'!A2336:B2336,2,FALSE) -> 17.58 | D2336: =VLOOKUP(A2336,'Medical Examinations'!A2336:C2336,3,FALSE) -> 4.51 | E2336: =VLOOKUP(A2336,'Medical Examinations'!A2336:D2336,4,FALSE) -> No | F2336: =VLOOKUP(A2336,'Medical Examinations'!A2336:E2336,5,FALSE) -> No | G2336: =VLOOKUP(A2336,'Medical Examinations'!A2336:F2336,6,FALSE) -> No | H2336: =VLOOKUP('HEALTH CARE'!A2336,'Medical Examinations'!A2336:G2336,7,FALSE) -> 1 | I2336: =VLOOKUP(A2336,'Medical Examinations'!A2336:H2336,8,FALSE) -> No | J2336: =VLOOKUP(A2336,'Medical Examinations'!A2336:I2336,9,FALSE) -> underweight | K2336: =VLOOKUP(A2336,'Medical Examinations'!A2336:J2336,10,FALSE) -> normal | L2336: =VLOOKUP(A2336,'Hospitalisation Details'!A:F, 5, FALSE) -> 9 | M2336: =VLOOKUP(A2336,'Hospitalisation Details'!A2336:H2336,8,FALSE) -> 563.84 | N2336: =VLOOKUP(A2336,'Hospitalisation Details'!A2336:I2336,9,FALSE) -> tier - 2 | O2336: =VLOOKUP(A2336,'Hospitalisation Details'!A2336:J2336,10,FALSE) -> tier - 3 | P2336: =VLOOKUP(A2336,'Hospitalisation Details'!A2336:K2336,11,FALSE) -> R1013 | Q2336: =VLOOKUP(A2336,'Hospitalisation Details'!A2336:L2336,12,FALSE) -> 30

Sheet DASHBOARD
